Workbook

Sheet Bolted Connections
A1: Joint ID | B1: Connection Material | C1: Gauge | D1: Number of Fasteners | E1: Bolt Type | F1: Bolt Diameter (in.) (d) | G1: Distance from bolt to closest end of connection Le (in.) | H1: Thickness (in.) | I1: Ultimate Strength (Fu) (ksi) | J1: Bearing Deformation (kips) | K1: h (in.) | L1: Lc (in.) | M1: Bolt Tear-Out Strength (kips) | N1: Bolt Bearing Strength (kips) | O1: AISC Bolt Category | P1: Nominal Shear Stress (ksi) | Q1: Bolt Area (in^2) | R1: Bolt Shear (kips) | S1: Max Shear Capacity (kips) | T1: Governing Mode | U1: Nominal Tensile Stess (ksi) | V1: Max Tension Capacity (kips)
H2: {=_xlfn.IFS(OR(B2="Carbon Steel Plate", B2="Carbon Steel Pipe", B2="Carbon Steel Tube"),VLOOKUP(C2,'Bolted Connection Data'!$A$3:$B$8,2,FALSE), OR(B2="Stainless Sheet Steel", B2="Stainless Steel Plate", B2="Stainless Steel Pipe"),VLOOKUP(C2,'Bolted Connection Data'!$E$3:$F$8,2,FALSE),B2="Galvanized Sheet Steel",VLOOKUP(C2,'Bolted Connection Data'!$A$3:$B$8,2,FALSE))} -> #N/A | I2: {=_xlfn.IFS(B2="Carbon Steel Plate",'Bolted Connection Data'!$N$4, B2="Carbon Steel Pipe",'Bolted Connection Data'!$N$5, B2="Carbon Steel Tube", 'Bolted Connection Data'!$N$6, B2="Galvanized Sheet Steel", 'Bolted Connection Data'!$N$2, B2="Stainless Sheet Steel", 'Bolted Connection Data'!$N$3, B2="Stainless Steel Plate", 'Bolted Connection Data'!$N$7, B2="Stainless Steel Pipe", 'Bolted Connection Data'!$N$8)} -> #N/A | J2: =2.4*F2*H2*I2 -> #N/A | K2: =IF(F2<1,F2+(1/16),F2) -> 0.0625 | L2: =G2-(K2/2) -> -0.03125 | M2: =1.2*L2*H2*I2 -> #N/A | N2: =MIN(J2,M2) -> #N/A | O2: {=_xlfn.IFS( E2="ASTM A307, Grade A",'Bolted Connection Data'!$E$17, 'Bolted Connections'!E2="ASTM A307, Grade A",'Bolted Connection Data'!$E$19, 'Bolted Connections'!E2='Bolted Connection Data'!$A$20,'Bolted Connection Data'!$E$20, 'Bolted Connections'!E2='Bolted Connection Data'!$A$23,'Bolted Connection Data'!$E$23, 'Bolted Connections'!E2='Bolted Connection Data'!$A$26,'Bolted Connection Data'!$E$26, 'Bolted Connections'!E2='Bolted Connection Data'!$A$28,'Bolted Connection Data'!$E$28, 'Bolted Connections'!E2='Bolted Connection Data'!$A$29,'Bolted Connection Data'!$E$29, 'Bolted Connections'!E2='Bolted Connection Data'!$A$31,'Bolted Connection Data'!$E$31 )} -> #N/A | P2: =VLOOKUP(O2,'Bolted Connection Data'!$A$45:$D$49,3,TRUE) -> #N/A | Q2: =(PI()*POWER(F2,2))/4 -> 0 | R2: =P2*Q2 -> #N/A | S2: =MIN(R2,N2)*D2*0.75 -> #N/A | T2: =IF(R2<N2,"Bolt Shear", "Bolt Bearing") -> #N/A | U2: =VLOOKUP(O2,'Bolted Connection Data'!$A$45:$D$49,2,TRUE) -> #N/A | V2: =0.75*U2*Q2*D2 -> #N/A
H3: {=_xlfn.IFS(OR(B3="Carbon Steel Plate", B3="Carbon Steel Pipe", B3="Carbon Steel Tube"),VLOOKUP(C3,'Bolted Connection Data'!$A$3:$B$8,2,FALSE), OR(B3="Stainless Sheet Steel", B3="Stainless Steel Plate", B3="Stainless Steel Pipe"),VLOOKUP(C3,'Bolted Connection Data'!$E$3:$F$8,2,FALSE),B3="Galvanized Sheet Steel",VLOOKUP(C3,'Bolted Connection Data'!$A$3:$B$8,2,FALSE))} -> #N/A | I3: {=_xlfn.IFS(B3="Carbon Steel Plate",'Bolted Connection Data'!$N$4, B3="Carbon Steel Pipe",'Bolted Connection Data'!$N$5, B3="Carbon Steel Tube", 'Bolted Connection Data'!$N$6, B3="Galvanized Sheet Steel", 'Bolted Connection Data'!$N$2, B3="Stainless Sheet Steel", 'Bolted Connection Data'!$N$3, B3="Stainless Steel Plate", 'Bolted Connection Data'!$N$7, B3="Stainless Steel Pipe", 'Bolted Connection Data'!$N$8)} -> #N/A | J3: =2.4*F3*H3*I3 -> #N/A | K3: =IF(F3<1,F3+(1/16),F3) -> 0.0625 | L3: =G3-(K3/2) -> -0.03125 | M3: =1.2*L3*H3*I3 -> #N/A | N3: =MIN(J3,M3) -> #N/A | O3: {=_xlfn.IFS( E3="ASTM A307, Grade A",'Bolted Connection Data'!$E$17, 'Bolted Connections'!E3="ASTM A307, Grade A",'Bolted Connection Data'!$E$19, 'Bolted Connections'!E3='Bolted Connection Data'!$A$20,'Bolted Connection Data'!$E$20, 'Bolted Connections'!E3='Bolted Connection Data'!$A$23,'Bolted Connection Data'!$E$23, 'Bolted Connections'!E3='Bolted Connection Data'!$A$26,'Bolted Connection Data'!$E$26, 'Bolted Connections'!E3='Bolted Connection Data'!$A$28,'Bolted Connection Data'!$E$28, 'Bolted Connections'!E3='Bolted Connection Data'!$A$29,'Bolted Connection Data'!$E$29, 'Bolted Connections'!E3='Bolted Connection Data'!$A$31,'Bolted Connection Data'!$E$31 )} -> #N/A | P3: =VLOOKUP(O3,'Bolted Connection Data'!$A$45:$D$49,3,TRUE) -> #N/A | Q3: =(PI()*POWER(F3,2))/4 -> 0 | R3: =P3*Q3 -> #N/A | S3: =MIN(R3,N3)*D3*0.75 -> #N/A | T3: =IF(R3<N3,"Bolt Shear", "Bolt Bearing") -> #N/A | U3: =VLOOKUP(O3,'Bolted Connection Data'!$A$45:$D$49,2,TRUE) -> #N/A | V3: =0.75*U3*Q3*D3 -> #N/A
H4: {=_xlfn.IFS(OR(B4="Carbon Steel Plate", B4="Carbon Steel Pipe", B4="Carbon Steel Tube"),VLOOKUP(C4,'Bolted Connection Data'!$A$3:$B$8,2,FALSE), OR(B4="Stainless Sheet Steel", B4="Stainless Steel Plate", B4="Stainless Steel Pipe"),VLOOKUP(C4,'Bolted Connection Data'!$E$3:$F$8,2,FALSE),B4="Galvanized Sheet Steel",VLOOKUP(C4,'Bolted Connection Data'!$A$3:$B$8,2,FALSE))} -> #N/A | I4: {=_xlfn.IFS(B4="Carbon Steel Plate",'Bolted Connection Data'!$N$4, B4="Carbon Steel Pipe",'Bolted Connection Data'!$N$5, B4="Carbon Steel Tube", 'Bolted Connection Data'!$N$6, B4="Galvanized Sheet Steel", 'Bolted Connection Data'!$N$2, B4="Stainless Sheet Steel", 'Bolted Connection Data'!$N$3, B4="Stainless Steel Plate", 'Bolted Connection Data'!$N$7, B4="Stainless Steel Pipe", 'Bolted Connection Data'!$N$8)} -> #N/A | J4: =2.4*F4*H4*I4 -> #N/A | K4: =IF(F4<1,F4+(1/16),F4) -> 0.0625 | L4: =G4-(K4/2) -> -0.03125 | M4: =1.2*L4*H4*I4 -> #N/A | N4: =MIN(J4,M4) -> #N/A | O4: {=_xlfn.IFS( E4="ASTM A307, Grade A",'Bolted Connection Data'!$E$17, 'Bolted Connections'!E4="ASTM A307, Grade A",'Bolted Connection Data'!$E$19, 'Bolted Connections'!E4='Bolted Connection Data'!$A$20,'Bolted Connection Data'!$E$20, 'Bolted Connections'!E4='Bolted Connection Data'!$A$23,'Bolted Connection Data'!$E$23, 'Bolted Connections'!E4='Bolted Connection Data'!$A$26,'Bolted Connection Data'!$E$26, 'Bolted Connections'!E4='Bolted Connection Data'!$A$28,'Bolted Connection Data'!$E$28, 'Bolted Connections'!E4='Bolted Connection Data'!$A$29,'Bolted Connection Data'!$E$29, 'Bolted Connections'!E4='Bolted Connection Data'!$A$31,'Bolted Connection Data'!$E$31 )} -> #N/A | P4: =VLOOKUP(O4,'Bolted Connection Data'!$A$45:$D$49,3,TRUE) -> #N/A | Q4: =(PI()*POWER(F4,2))/4 -> 0 | R4: =P4*Q4 -> #N/A | S4: =MIN(R4,N4)*D4*0.75 -> #N/A | T4: =IF(R4<N4,"Bolt Shear", "Bolt Bearing") -> #N/A | U4: =VLOOKUP(O4,'Bolted Connection Data'!$A$45:$D$49,2,TRUE) -> #N/A | V4: =0.75*U4*Q4*D4 -> #N/A
H5: {=_xlfn.IFS(OR(B5="Carbon Steel Plate", B5="Carbon Steel Pipe", B5="Carbon Steel Tube"),VLOOKUP(C5,'Bolted Connection Data'!$A$3:$B$8,2,FALSE), OR(B5="Stainless Sheet Steel", B5="Stainless Steel Plate", B5="Stainless Steel Pipe"),VLOOKUP(C5,'Bolted Connection Data'!$E$3:$F$8,2,FALSE),B5="Galvanized Sheet Steel",VLOOKUP(C5,'Bolted Connection Data'!$A$3:$B$8,2,FALSE))} -> #N/A | I5: {=_xlfn.IFS(B5="Carbon Steel Plate",'Bolted Connection Data'!$N$4, B5="Carbon Steel Pipe",'Bolted Connection Data'!$N$5, B5="Carbon Steel Tube", 'Bolted Connection Data'!$N$6, B5="Galvanized Sheet Steel", 'Bolted Connection Data'!$N$2, B5="Stainless Sheet Steel", 'Bolted Connection Data'!$N$3, B5="Stainless Steel Plate", 'Bolted Connection Data'!$N$7, B5="Stainless Steel Pipe", 'Bolted Connection Data'!$N$8)} -> #N/A | J5: =2.4*F5*H5*I5 -> #N/A | K5: =IF(F5<1,F5+(1/16),F5) -> 0.0625 | L5: =G5-(K5/2) -> -0.03125 | M5: =1.2*L5*H5*I5 -> #N/A | N5: =MIN(J5,M5) -> #N/A | O5: {=_xlfn.IFS( E5="ASTM A307, Grade A",'Bolted Connection Data'!$E$17, 'Bolted Connections'!E5="ASTM A307, Grade A",'Bolted Connection Data'!$E$19, 'Bolted Connections'!E5='Bolted Connection Data'!$A$20,'Bolted Connection Data'!$E$20, 'Bolted Connections'!E5='Bolted Connection Data'!$A$23,'Bolted Connection Data'!$E$23, 'Bolted Connections'!E5='Bolted Connection Data'!$A$26,'Bolted Connection Data'!$E$26, 'Bolted Connections'!E5='Bolted Connection Data'!$A$28,'Bolted Connection Data'!$E$28, 'Bolted Connections'!E5='Bolted Connection Data'!$A$29,'Bolted Connection Data'!$E$29, 'Bolted Connections'!E5='Bolted Connection Data'!$A$31,'Bolted Connection Data'!$E$31 )} -> #N/A | P5: =VLOOKUP(O5,'Bolted Connection Data'!$A$45:$D$49,3,TRUE) -> #N/A | Q5: =(PI()*POWER(F5,2))/4 -> 0 | R5: =P5*Q5 -> #N/A | S5: =MIN(R5,N5)*D5*0.75 -> #N/A | T5: =IF(R5<N5,"Bolt Shear", "Bolt Bearing") -> #N/A | U5: =VLOOKUP(O5,'Bolted Connection Data'!$A$45:$D$49,2,TRUE) -> #N/A | V5: =0.75*U5*Q5*D5 -> #N/A
H6: {=_xlfn.IFS(OR(B6="Carbon Steel Plate", B6="Carbon Steel Pipe", B6="Carbon Steel Tube"),VLOOKUP(C6,'Bolted Connection Data'!$A$3:$B$8,2,FALSE), OR(B6="Stainless Sheet Steel", B6="Stainless Steel Plate", B6="Stainless Steel Pipe"),VLOOKUP(C6,'Bolted Connection Data'!$E$3:$F$8,2,FALSE),B6="Galvanized Sheet Steel",VLOOKUP(C6,'Bolted Connection Data'!$A$3:$B$8,2,FALSE))} -> #N/A | I6: {=_xlfn.IFS(B6="Carbon Steel Plate",'Bolted Connection Data'!$N$4, B6="Carbon Steel Pipe",'Bolted Connection Data'!$N$5, B6="Carbon Steel Tube", 'Bolted Connection Data'!$N$6, B6="Galvanized Sheet Steel", 'Bolted Connection Data'!$N$2, B6="Stainless Sheet Steel", 'Bolted Connection Data'!$N$3, B6="Stainless Steel Plate", 'Bolted Connection Data'!$N$7, B6="Stainless Steel Pipe", 'Bolted Connection Data'!$N$8)} -> #N/A | J6: =2.4*F6*H6*I6 -> #N/A | K6: =IF(F6<1,F6+(1/16),F6) -> 0.0625 | L6: =G6-(K6/2) -> -0.03125 | M6: =1.2*L6*H6*I6 -> #N/A | N6: =MIN(J6,M6) -> #N/A | O6: {=_xlfn.IFS( E6="ASTM A307, Grade A",'Bolted Connection Data'!$E$17, 'Bolted Connections'!E6="ASTM A307, Grade A",'Bolted Connection Data'!$E$19, 'Bolted Connections'!E6='Bolted Connection Data'!$A$20,'Bolted Connection Data'!$E$20, 'Bolted Connections'!E6='Bolted Connection Data'!$A$23,'Bolted Connection Data'!$E$23, 'Bolted Connections'!E6='Bolted Connection Data'!$A$26,'Bolted Connection Data'!$E$26, 'Bolted Connections'!E6='Bolted Connection Data'!$A$28,'Bolted Connection Data'!$E$28, 'Bolted Connections'!E6='Bolted Connection Data'!$A$29,'Bolted Connection Data'!$E$29, 'Bolted Connections'!E6='Bolted Connection Data'!$A$31,'Bolted Connection Data'!$E$31 )} -> #N/A | P6: =VLOOKUP(O6,'Bolted Connection Data'!$A$45:$D$49,3,TRUE) -> #N/A | Q6: =(PI()*POWER(F6,2))/4 -> 0 | R6: =P6*Q6 -> #N/A | S6: =MIN(R6,N6)*D6*0.75 -> #N/A | T6: =IF(R6<N6,"Bolt Shear", "Bolt Bearing") -> #N/A | U6: =VLOOKUP(O6,'Bolted Connection Data'!$A$45:$D$49,2,TRUE) -> #N/A | V6: =0.75*U6*Q6*D6 -> #N/A
H7: {=_xlfn.IFS(OR(B7="Carbon Steel Plate", B7="Carbon Steel Pipe", B7="Carbon Steel Tube"),VLOOKUP(C7,'Bolted Connection Data'!$A$3:$B$8,2,FALSE), OR(B7="Stainless Sheet Steel", B7="Stainless Steel Plate", B7="Stainless Steel Pipe"),VLOOKUP(C7,'Bolted Connection Data'!$E$3:$F$8,2,FALSE),B7="Galvanized Sheet Steel",VLOOKUP(C7,'Bolted Connection Data'!$A$3:$B$8,2,FALSE))} -> #N/A | I7: {=_xlfn.IFS(B7="Carbon Steel Plate",'Bolted Connection Data'!$N$4, B7="Carbon Steel Pipe",'Bolted Connection Data'!$N$5, B7="Carbon Steel Tube", 'Bolted Connection Data'!$N$6, B7="Galvanized Sheet Steel", 'Bolted Connection Data'!$N$2, B7="Stainless Sheet Steel", 'Bolted Connection Data'!$N$3, B7="Stainless Steel Plate", 'Bolted Connection Data'!$N$7, B7="Stainless Steel Pipe", 'Bolted Connection Data'!$N$8)} -> #N/A | J7: =2.4*F7*H7*I7 -> #N/A | K7: =IF(F7<1,F7+(1/16),F7) -> 0.0625 | L7: =G7-(K7/2) -> -0.03125 | M7: =1.2*L7*H7*I7 -> #N/A | N7: =MIN(J7,M7) -> #N/A | O7: {=_xlfn.IFS( E7="ASTM A307, Grade A",'Bolted Connection Data'!$E$17, 'Bolted Connections'!E7="ASTM A307, Grade A",'Bolted Connection Data'!$E$19, 'Bolted Connections'!E7='Bolted Connection Data'!$A$20,'Bolted Connection Data'!$E$20, 'Bolted Connections'!E7='Bolted Connection Data'!$A$23,'Bolted Connection Data'!$E$23, 'Bolted Connections'!E7='Bolted Connection Data'!$A$26,'Bolted Connection Data'!$E$26, 'Bolted Connections'!E7='Bolted Connection Data'!$A$28,'Bolted Connection Data'!$E$28, 'Bolted Connections'!E7='Bolted Connection Data'!$A$29,'Bolted Connection Data'!$E$29, 'Bolted Connections'!E7='Bolted Connection Data'!$A$31,'Bolted Connection Data'!$E$31 )} -> #N/A | P7: =VLOOKUP(O7,'Bolted Connection Data'!$A$45:$D$49,3,TRUE) -> #N/A | Q7: =(PI()*POWER(F7,2))/4 -> 0 | R7: =P7*Q7 -> #N/A | S7: =MIN(R7,N7)*D7*0.75 -> #N/A | T7: =IF(R7<N7,"Bolt Shear", "Bolt Bearing") -> #N/A | U7: =VLOOKUP(O7,'Bolted Connection Data'!$A$45:$D$49,2,TRUE) -> #N/A | V7: =0.75*U7*Q7*D7 -> #N/A
H8: {=_xlfn.IFS(OR(B8="Carbon Steel Plate", B8="Carbon Steel Pipe", B8="Carbon Steel Tube"),VLOOKUP(C8,'Bolted Connection Data'!$A$3:$B$8,2,FALSE), OR(B8="Stainless Sheet Steel", B8="Stainless Steel Plate", B8="Stainless Steel Pipe"),VLOOKUP(C8,'Bolted Connection Data'!$E$3:$F$8,2,FALSE),B8="Galvanized Sheet Steel",VLOOKUP(C8,'Bolted Connection Data'!$A$3:$B$8,2,FALSE))} -> #N/A | I8: {=_xlfn.IFS(B8="Carbon Steel Plate",'Bolted Connection Data'!$N$4, B8="Carbon Steel Pipe",'Bolted Connection Data'!$N$5, B8="Carbon Steel Tube", 'Bolted Connection Data'!$N$6, B8="Galvanized Sheet Steel", 'Bolted Connection Data'!$N$2, B8="Stainless Sheet Steel", 'Bolted Connection Data'!$N$3, B8="Stainless Steel Plate", 'Bolted Connection Data'!$N$7, B8="Stainless Steel Pipe", 'Bolted Connection Data'!$N$8)} -> #N/A | J8: =2.4*F8*H8*I8 -> #N/A | K8: =IF(F8<1,F8+(1/16),F8) -> 0.0625 | L8: =G8-(K8/2) -> -0.03125 | M8: =1.2*L8*H8*I8 -> #N/A | N8: =MIN(J8,M8) -> #N/A | O8: {=_xlfn.IFS( E8="ASTM A307, Grade A",'Bolted Connection Data'!$E$17, 'Bolted Connections'!E8="ASTM A307, Grade A",'Bolted Connection Data'!$E$19, 'Bolted Connections'!E8='Bolted Connection Data'!$A$20,'Bolted Connection Data'!$E$20, 'Bolted Connections'!E8='Bolted Connection Data'!$A$23,'Bolted Connection Data'!$E$23, 'Bolted Connections'!E8='Bolted Connection Data'!$A$26,'Bolted Connection Data'!$E$26, 'Bolted Connections'!E8='Bolted Connection Data'!$A$28,'Bolted Connection Data'!$E$28, 'Bolted Connections'!E8='Bolted Connection Data'!$A$29,'Bolted Connection Data'!$E$29, 'Bolted Connections'!E8='Bolted Connection Data'!$A$31,'Bolted Connection Data'!$E$31 )} -> #N/A | P8: =VLOOKUP(O8,'Bolted Connection Data'!$A$45:$D$49,3,TRUE) -> #N/A | Q8: =(PI()*POWER(F8,2))/4 -> 0 | R8: =P8*Q8 -> #N/A | S8: =MIN(R8,N8)*D8*0.75 -> #N/A | T8: =IF(R8<N8,"Bolt Shear", "Bolt Bearing") -> #N/A | U8: =VLOOKUP(O8,'Bolted Connection Data'!$A$45:$D$49,2,TRUE) -> #N/A | V8: =0.75*U8*Q8*D8 -> #N/A
H9: {=_xlfn.IFS(OR(B9="Carbon Steel Plate", B9="Carbon Steel Pipe", B9="Carbon Steel Tube"),VLOOKUP(C9,'Bolted Connection Data'!$A$3:$B$8,2,FALSE), OR(B9="Stainless Sheet Steel", B9="Stainless Steel Plate", B9="Stainless Steel Pipe"),VLOOKUP(C9,'Bolted Connection Data'!$E$3:$F$8,2,FALSE),B9="Galvanized Sheet Steel",VLOOKUP(C9,'Bolted Connection Data'!$A$3:$B$8,2,FALSE))} -> #N/A | I9: {=_xlfn.IFS(B9="Carbon Steel Plate",'Bolted Connection Data'!$N$4, B9="Carbon Steel Pipe",'Bolted Connection Data'!$N$5, B9="Carbon Steel Tube", 'Bolted Connection Data'!$N$6, B9="Galvanized Sheet Steel", 'Bolted Connection Data'!$N$2, B9="Stainless Sheet Steel", 'Bolted Connection Data'!$N$3, B9="Stainless Steel Plate", 'Bolted Connection Data'!$N$7, B9="Stainless Steel Pipe", 'Bolted Connection Data'!$N$8)} -> #N/A | J9: =2.4*F9*H9*I9 -> #N/A | K9: =IF(F9<1,F9+(1/16),F9) -> 0.0625 | L9: =G9-(K9/2) -> -0.03125 | M9: =1.2*L9*H9*I9 -> #N/A | N9: =MIN(J9,M9) -> #N/A | O9: {=_xlfn.IFS( E9="ASTM A307, Grade A",'Bolted Connection Data'!$E$17, 'Bolted Connections'!E9="ASTM A307, Grade A",'Bolted Connection Data'!$E$19, 'Bolted Connections'!E9='Bolted Connection Data'!$A$20,'Bolted Connection Data'!$E$20, 'Bolted Connections'!E9='Bolted Connection Data'!$A$23,'Bolted Connection Data'!$E$23, 'Bolted Connections'!E9='Bolted Connection Data'!$A$26,'Bolted Connection Data'!$E$26, 'Bolted Connections'!E9='Bolted Connection Data'!$A$28,'Bolted Connection Data'!$E$28, 'Bolted Connections'!E9='Bolted Connection Data'!$A$29,'Bolted Connection Data'!$E$29, 'Bolted Connections'!E9='Bolted Connection Data'!$A$31,'Bolted Connection Data'!$E$31 )} -> #N/A | P9: =VLOOKUP(O9,'Bolted Connection Data'!$A$45:$D$49,3,TRUE) -> #N/A | Q9: =(PI()*POWER(F9,2))/4 -> 0 | R9: =P9*Q9 -> #N/A | S9: =MIN(R9,N9)*D9*0.75 -> #N/A | T9: =IF(R9<N9,"Bolt Shear", "Bolt Bearing") -> #N/A | U9: =VLOOKUP(O9,'Bolted Connection Data'!$A$45:$D$49,2,TRUE) -> #N/A | V9: =0.75*U9*Q9*D9 -> #N/A
H10: {=_xlfn.IFS(OR(B10="Carbon Steel Plate", B10="Carbon Steel Pipe", B10="Carbon Steel Tube"),VLOOKUP(C10,'Bolted Connection Data'!$A$3:$B$8,2,FALSE), OR(B10="Stainless Sheet Steel", B10="Stainless Steel Plate", B10="Stainless Steel Pipe"),VLOOKUP(C10,'Bolted Connection Data'!$E$3:$F$8,2,FALSE),B10="Galvanized Sheet Steel",VLOOKUP(C10,'Bolted Connection Data'!$A$3:$B$8,2,FALSE))} -> #N/A | I10: {=_xlfn.IFS(B10="Carbon Steel Plate",'Bolted Connection Data'!$N$4, B10="Carbon Steel Pipe",'Bolted Connection Data'!$N$5, B10="Carbon Steel Tube", 'Bolted Connection Data'!$N$6, B10="Galvanized Sheet Steel", 'Bolted Connection Data'!$N$2, B10="Stainless Sheet Steel", 'Bolted Connection Data'!$N$3, B10="Stainless Steel Plate", 'Bolted Connection Data'!$N$7, B10="Stainless Steel Pipe", 'Bolted Connection Data'!$N$8)} -> #N/A | J10: =2.4*F10*H10*I10 -> #N/A | K10: =IF(F10<1,F10+(1/16),F10) -> 0.0625 | L10: =G10-(K10/2) -> -0.03125 | M10: =1.2*L10*H10*I10 -> #N/A | N10: =MIN(J10,M10) -> #N/A | O10: {=_xlfn.IFS( E10="ASTM A307, Grade A",'Bolted Connection Data'!$E$17, 'Bolted Connections'!E10="ASTM A307, Grade A",'Bolted Connection Data'!$E$19, 'Bolted Connections'!E10='Bolted Connection Data'!$A$20,'Bolted Connection Data'!$E$20, 'Bolted Connections'!E10='Bolted Connection Data'!$A$23,'Bolted Connection Data'!$E$23, 'Bolted Connections'!E10='Bolted Connection Data'!$A$26,'Bolted Connection Data'!$E$26, 'Bolted Connections'!E10='Bolted Connection Data'!$A$28,'Bolted Connection Data'!$E$28, 'Bolted Connections'!E10='Bolted Connection Data'!$A$29,'Bolted Connection Data'!$E$29, 'Bolted Connections'!E10='Bolted Connection Data'!$A$31,'Bolted Connection Data'!$E$31 )} -> #N/A | P10: =VLOOKUP(O10,'Bolted Connection Data'!$A$45:$D$49,3,TRUE) -> #N/A | Q10: =(PI()*POWER(F10,2))/4 -> 0 | R10: =P10*Q10 -> #N/A | S10: =MIN(R10,N10)*D10*0.75 -> #N/A | T10: =IF(R10<N10,"Bolt Shear", "Bolt Bearing") -> #N/A | U10: =VLOOKUP(O10,'Bolted Connection Data'!$A$45:$D$49,2,TRUE) -> #N/A | V10: =0.75*U10*Q10*D10 -> #N/A
H11: {=_xlfn.IFS(OR(B11="Carbon Steel Plate", B11="Carbon Steel Pipe", B11="Carbon Steel Tube"),VLOOKUP(C11,'Bolted Connection Data'!$A$3:$B$8,2,FALSE), OR(B11="Stainless Sheet Steel", B11="Stainless Steel Plate", B11="Stainless Steel Pipe"),VLOOKUP(C11,'Bolted Connection Data'!$E$3:$F$8,2,FALSE),B11="Galvanized Sheet Steel",VLOOKUP(C11,'Bolted Connection Data'!$A$3:$B$8,2,FALSE))} -> #N/A | I11: {=_xlfn.IFS(B11="Carbon Steel Plate",'Bolted Connection Data'!$N$4, B11="Carbon Steel Pipe",'Bolted Connection Data'!$N$5, B11="Carbon Steel Tube", 'Bolted Connection Data'!$N$6, B11="Galvanized Sheet Steel", 'Bolted Connection Data'!$N$2, B11="Stainless Sheet Steel", 'Bolted Connection Data'!$N$3, B11="Stainless Steel Plate", 'Bolted Connection Data'!$N$7, B11="Stainless Steel Pipe", 'Bolted Connection Data'!$N$8)} -> #N/A | J11: =2.4*F11*H11*I11 -> #N/A | K11: =IF(F11<1,F11+(1/16),F11) -> 0.0625 | L11: =G11-(K11/2) -> -0.03125 | M11: =1.2*L11*H11*I11 -> #N/A | N11: =MIN(J11,M11) -> #N/A | O11: {=_xlfn.IFS( E11="ASTM A307, Grade A",'Bolted Connection Data'!$E$17, 'Bolted Connections'!E11="ASTM A307, Grade A",'Bolted Connection Data'!$E$19, 'Bolted Connections'!E11='Bolted Connection Data'!$A$20,'Bolted Connection Data'!$E$20, 'Bolted Connections'!E11='Bolted Connection Data'!$A$23,'Bolted Connection Data'!$E$23, 'Bolted Connections'!E11='Bolted Connection Data'!$A$26,'Bolted Connection Data'!$E$26, 'Bolted Connections'!E11='Bolted Connection Data'!$A$28,'Bolted Connection Data'!$E$28, 'Bolted Connections'!E11='Bolted Connection Data'!$A$29,'Bolted Connection Data'!$E$29, 'Bolted Connections'!E11='Bolted Connection Data'!$A$31,'Bolted Connection Data'!$E$31 )} -> #N/A | P11: =VLOOKUP(O11,'Bolted Connection Data'!$A$45:$D$49,3,TRUE) -> #N/A | Q11: =(PI()*POWER(F11,2))/4 -> 0 | R11: =P11*Q11 -> #N/A | S11: =MIN(R11,N11)*D11*0.75 -> #N/A | T11: =IF(R11<N11,"Bolt Shear", "Bolt Bearing") -> #N/A | U11: =VLOOKUP(O11,'Bolted Connection Data'!$A$45:$D$49,2,TRUE) -> #N/A | V11: =0.75*U11*Q11*D11 -> #N/A
H12: {=_xlfn.IFS(OR(B12="Carbon Steel Plate", B12="Carbon Steel Pipe", B12="Carbon Steel Tube"),VLOOKUP(C12,'Bolted Connection Data'!$A$3:$B$8,2,FALSE), OR(B12="Stainless Sheet Steel", B12="Stainless Steel Plate", B12="Stainless Steel Pipe"),VLOOKUP(C12,'Bolted Connection Data'!$E$3:$F$8,2,FALSE),B12="Galvanized Sheet Steel",VLOOKUP(C12,'Bolted Connection Data'!$A$3:$B$8,2,FALSE))} -> #N/A | I12: {=_xlfn.IFS(B12="Carbon Steel Plate",'Bolted Connection Data'!$N$4, B12="Carbon Steel Pipe",'Bolted Connection Data'!$N$5, B12="Carbon Steel Tube", 'Bolted Connection Data'!$N$6, B12="Galvanized Sheet Steel", 'Bolted Connection Data'!$N$2, B12="Stainless Sheet Steel", 'Bolted Connection Data'!$N$3, B12="Stainless Steel Plate", 'Bolted Connection Data'!$N$7, B12="Stainless Steel Pipe", 'Bolted Connection Data'!$N$8)} -> #N/A | J12: =2.4*F12*H12*I12 -> #N/A | K12: =IF(F12<1,F12+(1/16),F12) -> 0.0625 | L12: =G12-(K12/2) -> -0.03125 | M12: =1.2*L12*H12*I12 -> #N/A | N12: =MIN(J12,M12) -> #N/A | O12: {=_xlfn.IFS( E12="ASTM A307, Grade A",'Bolted Connection Data'!$E$17, 'Bolted Connections'!E12="ASTM A307, Grade A",'Bolted Connection Data'!$E$19, 'Bolted Connections'!E12='Bolted Connection Data'!$A$20,'Bolted Connection Data'!$E$20, 'Bolted Connections'!E12='Bolted Connection Data'!$A$23,'Bolted Connection Data'!$E$23, 'Bolted Connections'!E12='Bolted Connection Data'!$A$26,'Bolted Connection Data'!$E$26, 'Bolted Connections'!E12='Bolted Connection Data'!$A$28,'Bolted Connection Data'!$E$28, 'Bolted Connections'!E12='Bolted Connection Data'!$A$29,'Bolted Connection Data'!$E$29, 'Bolted Connections'!E12='Bolted Connection Data'!$A$31,'Bolted Connection Data'!$E$31 )} -> #N/A | P12: =VLOOKUP(O12,'Bolted Connection Data'!$A$45:$D$49,3,TRUE) -> #N/A | Q12: =(PI()*POWER(F12,2))/4 -> 0 | R12: =P12*Q12 -> #N/A | S12: =MIN(R12,N12)*D12*0.75 -> #N/A | T12: =IF(R12<N12,"Bolt Shear", "Bolt Bearing") -> #N/A | U12: =VLOOKUP(O12,'Bolted Connection Data'!$A$45:$D$49,2,TRUE) -> #N/A | V12: =0.75*U12*Q12*D12 -> #N/A
H13: {=_xlfn.IFS(OR(B13="Carbon Steel Plate", B13="Carbon Steel Pipe", B13="Carbon Steel Tube"),VLOOKUP(C13,'Bolted Connection Data'!$A$3:$B$8,2,FALSE), OR(B13="Stainless Sheet Steel", B13="Stainless Steel Plate", B13="Stainless Steel Pipe"),VLOOKUP(C13,'Bolted Connection Data'!$E$3:$F$8,2,FALSE),B13="Galvanized Sheet Steel",VLOOKUP(C13,'Bolted Connection Data'!$A$3:$B$8,2,FALSE))} -> #N/A | I13: {=_xlfn.IFS(B13="Carbon Steel Plate",'Bolted Connection Data'!$N$4, B13="Carbon Steel Pipe",'Bolted Connection Data'!$N$5, B13="Carbon Steel Tube", 'Bolted Connection Data'!$N$6, B13="Galvanized Sheet Steel", 'Bolted Connection Data'!$N$2, B13="Stainless Sheet Steel", 'Bolted Connection Data'!$N$3, B13="Stainless Steel Plate", 'Bolted Connection Data'!$N$7, B13="Stainless Steel Pipe", 'Bolted Connection Data'!$N$8)} -> #N/A | J13: =2.4*F13*H13*I13 -> #N/A | K13: =IF(F13<1,F13+(1/16),F13) -> 0.0625 | L13: =G13-(K13/2) -> -0.03125 | M13: =1.2*L13*H13*I13 -> #N/A | N13: =MIN(J13,M13) -> #N/A | O13: {=_xlfn.IFS( E13="ASTM A307, Grade A",'Bolted Connection Data'!$E$17, 'Bolted Connections'!E13="ASTM A307, Grade A",'Bolted Connection Data'!$E$19, 'Bolted Connections'!E13='Bolted Connection Data'!$A$20,'Bolted Connection Data'!$E$20, 'Bolted Connections'!E13='Bolted Connection Data'!$A$23,'Bolted Connection Data'!$E$23, 'Bolted Connections'!E13='Bolted Connection Data'!$A$26,'Bolted Connection Data'!$E$26, 'Bolted Connections'!E13='Bolted Connection Data'!$A$28,'Bolted Connection Data'!$E$28, 'Bolted Connections'!E13='Bolted Connection Data'!$A$29,'Bolted Connection Data'!$E$29, 'Bolted Connections'!E13='Bolted Connection Data'!$A$31,'Bolted Connection Data'!$E$31 )} -> #N/A | P13: =VLOOKUP(O13,'Bolted Connection Data'!$A$45:$D$49,3,TRUE) -> #N/A | Q13: =(PI()*POWER(F13,2))/4 -> 0 | R13: =P13*Q13 -> #N/A | S13: =MIN(R13,N13)*D13*0.75 -> #N/A | T13: =IF(R13<N13,"Bolt Shear", "Bolt Bearing") -> #N/A | U13: =VLOOKUP(O13,'Bolted Connection Data'!$A$45:$D$49,2,TRUE) -> #N/A | V13: =0.75*U13*Q13*D13 -> #N/A
... H1000: {=_xlfn.IFS(OR(B1000="Carbon Steel Plate", B1000="Carbon Steel Pipe", B1000="Carbon Steel Tube"),VLOOKUP(C1000,'Bolted Connection Data'!$A$3:$B$8,2,FALSE), OR(B1000="Stainless Sheet Steel", B1000="Stainless Steel Plate", B1000="Stainless Steel Pipe"),VLOOKUP(C1000,'Bolted Connection Data'!$E$3:$F$8,2,FALSE),B1000="Galvanized Sheet Steel",VLOOKUP(C1000,'Bolted Connection Data'!$A$3:$B$8,2,FALSE))} -> #N/A | I1000: {=_xlfn.IFS(B1000="Carbon Steel Plate",'Bolted Connection Data'!$N$4, B1000="Carbon Steel Pipe",'Bolted Connection Data'!$N$5, B1000="Carbon Steel Tube", 'Bolted Connection Data'!$N$6, B1000="Galvanized Sheet Steel", 'Bolted Connection Data'!$N$2, B1000="Stainless Sheet Steel", 'Bolted Connection Data'!$N$3, B1000="Stainless Steel Plate", 'Bolted Connection Data'!$N$7, B1000="Stainless Steel Pipe", 'Bolted Connection Data'!$N$8)} -> #N/A | J1000: =2.4*F1000*H1000*I1000 -> #N/A | K1000: =IF(F1000<1,F1000+(1/16),F1000) -> 0.0625 | L1000: =G1000-(K1000/2) -> -0.03125 | M1000: =1.2*L1000*H1000*I1000 -> #N/A | N1000: =MIN(J1000,M1000) -> #N/A | O1000: {=_xlfn.IFS( E1000="ASTM A307, Grade A",'Bolted Connection Data'!$E$17, 'Bolted Connections'!E1000="ASTM A307, Grade A",'Bolted Connection Data'!$E$19, 'Bolted Connections'!E1000='Bolted Connection Data'!$A$20,'Bolted Connection Data'!$E$20, 'Bolted Connections'!E1000='Bolted Connection Data'!$A$23,'Bolted Connection Data'!$E$23, 'Bolted Connections'!E1000='Bolted Connection Data'!$A$26,'Bolted Connection Data'!$E$26, 'Bolted Connections'!E1000='Bolted Connection Data'!$A$28,'Bolted Connection Data'!$E$28, 'Bolted Connections'!E1000='Bolted Connection Data'!$A$29,'Bolted Connection Data'!$E$29, 'Bolted Connections'!E1000='Bolted Connection Data'!$A$31,'Bolted Connection Data'!$E$31 )} -> #N/A | P1000: =VLOOKUP(O1000,'Bolted Connection Data'!$A$45:$D$49,3,TRUE) -> #N/A | Q1000: =(PI()*POWER(F1000,2))/4 -> 0 | R1000: =P1000*Q1000 -> #N/A | S1000: =MIN(R1000,N1000)*D1000*0.75 -> #N/A | T1000: =IF(R1000<N1000,"Bolt Shear", "Bolt Bearing") -> #N/A | U1000: =VLOOKUP(O1000,'Bolted Connection Data'!$A$45:$D$49,2,TRUE) -> #N/A | V1000: =0.75*U1000*Q1000*D1000 -> #N/A

Sheet Bolted Connection Data
A1: Carbon Steel/Galvanized | E1: Stainless Steel | M1: Material | N1: Ultimate Strength | P1: Gauges
A2: Steel Gauge | B2: Minimum Thickness | E2: Steel Gauge | F2: Minimum Thickness | M2: Galvanized Sheet Steel | N2: 19 | P2: 8
A3: 8 | B3: 0.153 | E3: 8 | F3: 0.151 | M3: Stainless Sheet Steel | N3: 20 | P3: 10
A4: 10 | B4: 0.127 | E4: 10 | F4: 0.122 | M4: Carbon Steel Plate | N4: 21 | P4: 12
A5: 12 | B5: 0.095 | E5: 12 | F5: 0.096 | M5: Carbon Steel Pipe | N5: 20 | P5: 14
A6: 14 | B6: 0.067 | E6: 14 | F6: 0.071 | M6: Carbon Steel Tube | N6: 27 | P6: 16
A7: 16 | B7: 0.054 | E7: 16 | F7: 0.056 | M7: Stainless Steel Plate | N7: 17 | P7: 18
A8: 18 | B8: 0.044 | E8: 18 | F8: 0.045 | M8: Stainless Steel Pipe | N8: 17
A15: Bolt Data
A16: Screw Type | B16: Size Min (in) | C16: Size Max (in) | D16: Tensile Strength (Fu) | E16: AISC Group | G16: Type | H16: Size Min (in) | I16: Size Max (in) | J16: Tensile Strength (Fu) | K16: AISC Group)
A17: ASTM A307, Grade A | B17: 0.25 | C17: 0.375 | D17: 60 | E17: A307
B18: 0.5 | C18: 1
A19: ASTM F3125, Grade A325, Type 1 | B19: 0.5 | C19: 1 | D19: 120 | E19: Group 120
A20: SAE J429, Grade 2 | B20: 0.25 | C20: 0.375 | D20: 74 | E20: A307
B21: 0.5 | C21: 0.75
B22: 0.875 | C22: 1.5 | D22: 60
A23: SAE J429, Grade 5 | B23: 0.25 | C23: 0.375 | D23: 120 | E23: Group 120
B24: 0.5 | C24: 1
B25: 1.125 | C25: 1.5 | D25: 105
A26: SAE J429, Grade 8 | B26: 0.25 | C26: 0.375 | D26: 150 | E26: Group 150
B27: 0.5 | C27: 1.5
A28: ASTM F593, Type 304/316, Condition A, annealed | B28: 0.25 | C28: 1.25 | D28: 70 | E28: A307
A29: ASTM A193, Grade B8, Class 2, Type 304 | B29: 0.25 | C29: 0.75 | D29: 125 | E29: Group 120
B30: 0.875 | C30: 1 | D30: 115
A31: ASTM F468, Ni 500 | B31: 0.25 | C31: 1.25 | D31: 130 | E31: Group 150
A44: Description of Fasteners | B44: Nominal Tensilte Stress (ksi) | C44: Nomianl Shear Stress (Threads NOT Exluded) | D44: Nominal Shear Stress (Threads Excluded)
A45: A307 | B45: 45 | C45: 27 | D45: 27
A46: Group 120 | B46: 90 | C46: 54 | D46: 68
A47: Group 144 | B47: 108 | C47: 65 | D47: 81
A48: Group 150 | B48: 113 | C48: 68 | D48: 84
A49: Group 200 | B49: 150 | C49: 90 | D49: 113

Sheet Welded Connections
A1: Joint ID | B1: Branch Name | C1: Branch Material | D1: Branch Gauge | E1: Branch Thickness (in.) | F1: Branch Width (in.) | G1: Branch Height (in.) | H1: Chord Name | I1: Chord Material | J1: Chord Gauge | K1: Chord Thickness (in.) | L1: Electrode Specification (EXXXX) | M1: Branch Nominal Shear Stress (ksi) | N1: Chord Nominal Shear Stress 1 (ksi) | O1: Base Metal Area (in. ^ 2) | P1: Weld Length (in.) | Q1: Fexx (ksi) | R1: Weld Leg Size (in.) | S1: Base Material Strength (kips) | T1: Weld Shear Strength (kips) | U1: Max Shear Capacity (kips) | V1: Governing Mode
E2: =VLOOKUP(D2,'Welded Connection Data'!$P$2:$Q$11,2,FALSE) -> #N/A | K2: =VLOOKUP(J2,'Welded Connection Data'!$P$2:$Q$11,2,FALSE) -> #N/A | M2: {=_xlfn.IFS(C2="Stainless Steel Tube",'Welded Connection Data'!$N$9,C2="Carbon Steel Tube",'Welded Connection Data'!$N$6)} -> #N/A | N2: {=_xlfn.IFS(I2="Stainless Steel Tube",'Welded Connection Data'!$N$9,I2="Carbon Steel Tube",'Welded Connection Data'!$N$6)} -> #N/A | O2: =F2*G2-((F2-2*E2)*(G2-2*E2)) -> #N/A | P2: =F2+G2 -> 0 | Q2: =VALUE(MID(L2, 2, 1)) * 10 -> #VALUE! | R2: {=_xlfn.IFS(MIN(E2,K2)<=0.25,0.125, AND(MIN(E2,K2)>0.25, MIN(E2,K2)<=0.5),0.1875, AND(MIN(E2,K2)>0.5, MIN(E2,K2)<=0.75),0.25, TRUE, 0.3125)} -> #N/A | S2: =MIN(M2,N2)*O2 -> #N/A | T2: =0.75*0.6*Q2*0.707*R2*P2 -> #VALUE! | U2: =MIN(S2,T2) -> #N/A | V2: =IF(S2<T2,"Base Material Strength","Weld Shear Strength") -> #N/A
E3: =VLOOKUP(D3,'Welded Connection Data'!$P$2:$Q$11,2,FALSE) -> #N/A | K3: =VLOOKUP(J3,'Welded Connection Data'!$P$2:$Q$11,2,FALSE) -> #N/A | M3: {=_xlfn.IFS(C3="Stainless Steel Tube",'Welded Connection Data'!$N$9,C3="Carbon Steel Tube",'Welded Connection Data'!$N$6)} -> #N/A | N3: {=_xlfn.IFS(I3="Stainless Steel Tube",'Welded Connection Data'!$N$9,I3="Carbon Steel Tube",'Welded Connection Data'!$N$6)} -> #N/A | O3: =F3*G3-((F3-2*E3)*(G3-2*E3)) -> #N/A | P3: =F3+G3 -> 0 | Q3: =VALUE(MID(L3, 2, 1)) * 10 -> #VALUE! | R3: {=_xlfn.IFS(MIN(E3,K3)<=0.25,0.125, AND(MIN(E3,K3)>0.25, MIN(E3,K3)<=0.5),0.1875, AND(MIN(E3,K3)>0.5, MIN(E3,K3)<=0.75),0.25, TRUE, 0.3125)} -> #N/A | S3: =MIN(M3,N3)*O3 -> #N/A | T3: =0.75*0.6*Q3*0.707*R3*P3 -> #VALUE! | U3: =MIN(S3,T3) -> #N/A | V3: =IF(S3<T3,"Base Material Strength","Weld Shear Strength") -> #N/A
E4: =VLOOKUP(D4,'Welded Connection Data'!$P$2:$Q$11,2,FALSE) -> #N/A | K4: =VLOOKUP(J4,'Welded Connection Data'!$P$2:$Q$11,2,FALSE) -> #N/A | M4: {=_xlfn.IFS(C4="Stainless Steel Tube",'Welded Connection Data'!$N$9,C4="Carbon Steel Tube",'Welded Connection Data'!$N$6)} -> #N/A | N4: {=_xlfn.IFS(I4="Stainless Steel Tube",'Welded Connection Data'!$N$9,I4="Carbon Steel Tube",'Welded Connection Data'!$N$6)} -> #N/A | O4: =F4*G4-((F4-2*E4)*(G4-2*E4)) -> #N/A | P4: =F4+G4 -> 0 | Q4: =VALUE(MID(L4, 2, 1)) * 10 -> #VALUE! | R4: {=_xlfn.IFS(MIN(E4,K4)<=0.25,0.125, AND(MIN(E4,K4)>0.25, MIN(E4,K4)<=0.5),0.1875, AND(MIN(E4,K4)>0.5, MIN(E4,K4)<=0.75),0.25, TRUE, 0.3125)} -> #N/A | S4: =MIN(M4,N4)*O4 -> #N/A | T4: =0.75*0.6*Q4*0.707*R4*P4 -> #VALUE! | U4: =MIN(S4,T4) -> #N/A | V4: =IF(S4<T4,"Base Material Strength","Weld Shear Strength") -> #N/A
E5: =VLOOKUP(D5,'Welded Connection Data'!$P$2:$Q$11,2,FALSE) -> #N/A | K5: =VLOOKUP(J5,'Welded Connection Data'!$P$2:$Q$11,2,FALSE) -> #N/A | M5: {=_xlfn.IFS(C5="Stainless Steel Tube",'Welded Connection Data'!$N$9,C5="Carbon Steel Tube",'Welded Connection Data'!$N$6)} -> #N/A | N5: {=_xlfn.IFS(I5="Stainless Steel Tube",'Welded Connection Data'!$N$9,I5="Carbon Steel Tube",'Welded Connection Data'!$N$6)} -> #N/A | O5: =F5*G5-((F5-2*E5)*(G5-2*E5)) -> #N/A | P5: =F5+G5 -> 0 | Q5: =VALUE(MID(L5, 2, 1)) * 10 -> #VALUE! | R5: {=_xlfn.IFS(MIN(E5,K5)<=0.25,0.125, AND(MIN(E5,K5)>0.25, MIN(E5,K5)<=0.5),0.1875, AND(MIN(E5,K5)>0.5, MIN(E5,K5)<=0.75),0.25, TRUE, 0.3125)} -> #N/A | S5: =MIN(M5,N5)*O5 -> #N/A | T5: =0.75*0.6*Q5*0.707*R5*P5 -> #VALUE! | U5: =MIN(S5,T5) -> #N/A | V5: =IF(S5<T5,"Base Material Strength","Weld Shear Strength") -> #N/A
E6: =VLOOKUP(D6,'Welded Connection Data'!$P$2:$Q$11,2,FALSE) -> #N/A | K6: =VLOOKUP(J6,'Welded Connection Data'!$P$2:$Q$11,2,FALSE) -> #N/A | M6: {=_xlfn.IFS(C6="Stainless Steel Tube",'Welded Connection Data'!$N$9,C6="Carbon Steel Tube",'Welded Connection Data'!$N$6)} -> #N/A | N6: {=_xlfn.IFS(I6="Stainless Steel Tube",'Welded Connection Data'!$N$9,I6="Carbon Steel Tube",'Welded Connection Data'!$N$6)} -> #N/A | O6: =F6*G6-((F6-2*E6)*(G6-2*E6)) -> #N/A | P6: =F6+G6 -> 0 | Q6: =VALUE(MID(L6, 2, 1)) * 10 -> #VALUE! | R6: {=_xlfn.IFS(MIN(E6,K6)<=0.25,0.125, AND(MIN(E6,K6)>0.25, MIN(E6,K6)<=0.5),0.1875, AND(MIN(E6,K6)>0.5, MIN(E6,K6)<=0.75),0.25, TRUE, 0.3125)} -> #N/A | S6: =MIN(M6,N6)*O6 -> #N/A | T6: =0.75*0.6*Q6*0.707*R6*P6 -> #VALUE! | U6: =MIN(S6,T6) -> #N/A | V6: =IF(S6<T6,"Base Material Strength","Weld Shear Strength") -> #N/A
E7: =VLOOKUP(D7,'Welded Connection Data'!$P$2:$Q$11,2,FALSE) -> #N/A | K7: =VLOOKUP(J7,'Welded Connection Data'!$P$2:$Q$11,2,FALSE) -> #N/A | M7: {=_xlfn.IFS(C7="Stainless Steel Tube",'Welded Connection Data'!$N$9,C7="Carbon Steel Tube",'Welded Connection Data'!$N$6)} -> #N/A | N7: {=_xlfn.IFS(I7="Stainless Steel Tube",'Welded Connection Data'!$N$9,I7="Carbon Steel Tube",'Welded Connection Data'!$N$6)} -> #N/A | O7: =F7*G7-((F7-2*E7)*(G7-2*E7)) -> #N/A | P7: =F7+G7 -> 0 | Q7: =VALUE(MID(L7, 2, 1)) * 10 -> #VALUE! | R7: {=_xlfn.IFS(MIN(E7,K7)<=0.25,0.125, AND(MIN(E7,K7)>0.25, MIN(E7,K7)<=0.5),0.1875, AND(MIN(E7,K7)>0.5, MIN(E7,K7)<=0.75),0.25, TRUE, 0.3125)} -> #N/A | S7: =MIN(M7,N7)*O7 -> #N/A | T7: =0.75*0.6*Q7*0.707*R7*P7 -> #VALUE! | U7: =MIN(S7,T7) -> #N/A | V7: =IF(S7<T7,"Base Material Strength","Weld Shear Strength") -> #N/A
E8: =VLOOKUP(D8,'Welded Connection Data'!$P$2:$Q$11,2,FALSE) -> #N/A | K8: =VLOOKUP(J8,'Welded Connection Data'!$P$2:$Q$11,2,FALSE) -> #N/A | M8: {=_xlfn.IFS(C8="Stainless Steel Tube",'Welded Connection Data'!$N$9,C8="Carbon Steel Tube",'Welded Connection Data'!$N$6)} -> #N/A | N8: {=_xlfn.IFS(I8="Stainless Steel Tube",'Welded Connection Data'!$N$9,I8="Carbon Steel Tube",'Welded Connection Data'!$N$6)} -> #N/A | O8: =F8*G8-((F8-2*E8)*(G8-2*E8)) -> #N/A | P8: =F8+G8 -> 0 | Q8: =VALUE(MID(L8, 2, 1)) * 10 -> #VALUE! | R8: {=_xlfn.IFS(MIN(E8,K8)<=0.25,0.125, AND(MIN(E8,K8)>0.25, MIN(E8,K8)<=0.5),0.1875, AND(MIN(E8,K8)>0.5, MIN(E8,K8)<=0.75),0.25, TRUE, 0.3125)} -> #N/A | S8: =MIN(M8,N8)*O8 -> #N/A | T8: =0.75*0.6*Q8*0.707*R8*P8 -> #VALUE! | U8: =MIN(S8,T8) -> #N/A | V8: =IF(S8<T8,"Base Material Strength","Weld Shear Strength") -> #N/A
E9: =VLOOKUP(D9,'Welded Connection Data'!$P$2:$Q$11,2,FALSE) -> #N/A | K9: =VLOOKUP(J9,'Welded Connection Data'!$P$2:$Q$11,2,FALSE) -> #N/A | M9: {=_xlfn.IFS(C9="Stainless Steel Tube",'Welded Connection Data'!$N$9,C9="Carbon Steel Tube",'Welded Connection Data'!$N$6)} -> #N/A | N9: {=_xlfn.IFS(I9="Stainless Steel Tube",'Welded Connection Data'!$N$9,I9="Carbon Steel Tube",'Welded Connection Data'!$N$6)} -> #N/A | O9: =F9*G9-((F9-2*E9)*(G9-2*E9)) -> #N/A | P9: =F9+G9 -> 0 | Q9: =VALUE(MID(L9, 2, 1)) * 10 -> #VALUE! | R9: {=_xlfn.IFS(MIN(E9,K9)<=0.25,0.125, AND(MIN(E9,K9)>0.25, MIN(E9,K9)<=0.5),0.1875, AND(MIN(E9,K9)>0.5, MIN(E9,K9)<=0.75),0.25, TRUE, 0.3125)} -> #N/A | S9: =MIN(M9,N9)*O9 -> #N/A | T9: =0.75*0.6*Q9*0.707*R9*P9 -> #VALUE! | U9: =MIN(S9,T9) -> #N/A | V9: =IF(S9<T9,"Base Material Strength","Weld Shear Strength") -> #N/A
E10: =VLOOKUP(D10,'Welded Connection Data'!$P$2:$Q$11,2,FALSE) -> #N/A | K10: =VLOOKUP(J10,'Welded Connection Data'!$P$2:$Q$11,2,FALSE) -> #N/A | M10: {=_xlfn.IFS(C10="Stainless Steel Tube",'Welded Connection Data'!$N$9,C10="Carbon Steel Tube",'Welded Connection Data'!$N$6)} -> #N/A | N10: {=_xlfn.IFS(I10="Stainless Steel Tube",'Welded Connection Data'!$N$9,I10="Carbon Steel Tube",'Welded Connection Data'!$N$6)} -> #N/A | O10: =F10*G10-((F10-2*E10)*(G10-2*E10)) -> #N/A | P10: =F10+G10 -> 0 | Q10: =VALUE(MID(L10, 2, 1)) * 10 -> #VALUE! | R10: {=_xlfn.IFS(MIN(E10,K10)<=0.25,0.125, AND(MIN(E10,K10)>0.25, MIN(E10,K10)<=0.5),0.1875, AND(MIN(E10,K10)>0.5, MIN(E10,K10)<=0.75),0.25, TRUE, 0.3125)} -> #N/A | S10: =MIN(M10,N10)*O10 -> #N/A | T10: =0.75*0.6*Q10*0.707*R10*P10 -> #VALUE! | U10: =MIN(S10,T10) -> #N/A | V10: =IF(S10<T10,"Base Material Strength","Weld Shear Strength") -> #N/A
E11: =VLOOKUP(D11,'Welded Connection Data'!$P$2:$Q$11,2,FALSE) -> #N/A | K11: =VLOOKUP(J11,'Welded Connection Data'!$P$2:$Q$11,2,FALSE) -> #N/A | M11: {=_xlfn.IFS(C11="Stainless Steel Tube",'Welded Connection Data'!$N$9,C11="Carbon Steel Tube",'Welded Connection Data'!$N$6)} -> #N/A | N11: {=_xlfn.IFS(I11="Stainless Steel Tube",'Welded Connection Data'!$N$9,I11="Carbon Steel Tube",'Welded Connection Data'!$N$6)} -> #N/A | O11: =F11*G11-((F11-2*E11)*(G11-2*E11)) -> #N/A | P11: =F11+G11 -> 0 | Q11: =VALUE(MID(L11, 2, 1)) * 10 -> #VALUE! | R11: {=_xlfn.IFS(MIN(E11,K11)<=0.25,0.125, AND(MIN(E11,K11)>0.25, MIN(E11,K11)<=0.5),0.1875, AND(MIN(E11,K11)>0.5, MIN(E11,K11)<=0.75),0.25, TRUE, 0.3125)} -> #N/A | S11: =MIN(M11,N11)*O11 -> #N/A | T11: =0.75*0.6*Q11*0.707*R11*P11 -> #VALUE! | U11: =MIN(S11,T11) -> #N/A | V11: =IF(S11<T11,"Base Material Strength","Weld Shear Strength") -> #N/A
E12: =VLOOKUP(D12,'Welded Connection Data'!$P$2:$Q$11,2,FALSE) -> #N/A | K12: =VLOOKUP(J12,'Welded Connection Data'!$P$2:$Q$11,2,FALSE) -> #N/A | M12: {=_xlfn.IFS(C12="Stainless Steel Tube",'Welded Connection Data'!$N$9,C12="Carbon Steel Tube",'Welded Connection Data'!$N$6)} -> #N/A | N12: {=_xlfn.IFS(I12="Stainless Steel Tube",'Welded Connection Data'!$N$9,I12="Carbon Steel Tube",'Welded Connection Data'!$N$6)} -> #N/A | O12: =F12*G12-((F12-2*E12)*(G12-2*E12)) -> #N/A | P12: =F12+G12 -> 0 | Q12: =VALUE(MID(L12, 2, 1)) * 10 -> #VALUE! | R12: {=_xlfn.IFS(MIN(E12,K12)<=0.25,0.125, AND(MIN(E12,K12)>0.25, MIN(E12,K12)<=0.5),0.1875, AND(MIN(E12,K12)>0.5, MIN(E12,K12)<=0.75),0.25, TRUE, 0.3125)} -> #N/A | S12: =MIN(M12,N12)*O12 -> #N/A | T12: =0.75*0.6*Q12*0.707*R12*P12 -> #VALUE! | U12: =MIN(S12,T12) -> #N/A | V12: =IF(S12<T12,"Base Material Strength","Weld Shear Strength") -> #N/A
E13: =VLOOKUP(D13,'Welded Connection Data'!$P$2:$Q$11,2,FALSE) -> #N/A | K13: =VLOOKUP(J13,'Welded Connection Data'!$P$2:$Q$11,2,FALSE) -> #N/A | M13: {=_xlfn.IFS(C13="Stainless Steel Tube",'Welded Connection Data'!$N$9,C13="Carbon Steel Tube",'Welded Connection Data'!$N$6)} -> #N/A | N13: {=_xlfn.IFS(I13="Stainless Steel Tube",'Welded Connection Data'!$N$9,I13="Carbon Steel Tube",'Welded Connection Data'!$N$6)} -> #N/A | O13: =F13*G13-((F13-2*E13)*(G13-2*E13)) -> #N/A | P13: =F13+G13 -> 0 | Q13: =VALUE(MID(L13, 2, 1)) * 10 -> #VALUE! | R13: {=_xlfn.IFS(MIN(E13,K13)<=0.25,0.125, AND(MIN(E13,K13)>0.25, MIN(E13,K13)<=0.5),0.1875, AND(MIN(E13,K13)>0.5, MIN(E13,K13)<=0.75),0.25, TRUE, 0.3125)} -> #N/A | S13: =MIN(M13,N13)*O13 -> #N/A | T13: =0.75*0.6*Q13*0.707*R13*P13 -> #VALUE! | U13: =MIN(S13,T13) -> #N/A | V13: =IF(S13<T13,"Base Material Strength","Weld Shear Strength") -> #N/A
... E1000: =VLOOKUP(D1000,'Welded Connection Data'!$P$2:$Q$11,2,FALSE) -> #N/A | K1000: =VLOOKUP(J1000,'Welded Connection Data'!$P$2:$Q$11,2,FALSE) -> #N/A | M1000: {=_xlfn.IFS(C1000="Stainless Steel Tube",'Welded Connection Data'!$N$9,C1000="Carbon Steel Tube",'Welded Connection Data'!$N$6)} -> #N/A | N1000: {=_xlfn.IFS(I1000="Stainless Steel Tube",'Welded Connection Data'!$N$9,I1000="Carbon Steel Tube",'Welded Connection Data'!$N$6)} -> #N/A | O1000: =F1000*G1000-((F1000-2*E1000)*(G1000-2*E1000)) -> #N/A | P1000: =F1000+G1000 -> 0 | Q1000: =VALUE(MID(L1000, 2, 1)) * 10 -> #VALUE! | R1000: {=_xlfn.IFS(MIN(E1000,K1000)<=0.25,0.125, AND(MIN(E1000,K1000)>0.25, MIN(E1000,K1000)<=0.5),0.1875, AND(MIN(E1000,K1000)>0.5, MIN(E1000,K1000)<=0.75),0.25, TRUE, 0.3125)} -> #N/A | S1000: =MIN(M1000,N1000)*O1000 -> #N/A | T1000: =0.75*0.6*Q1000*0.707*R1000*P1000 -> #VALUE! | U1000: =MIN(S1000,T1000) -> #N/A | V1000: =IF(S1000<T1000,"Base Material Strength","Weld Shear Strength") -> #N/A

Sheet Welded Connection Data
M1: Material | N1: Ultimate Strength | P1: Gauges | Q1: Thicknesses
M2: Galvanized Sheet Steel | N2: 19 | P2: 8 | Q2: 0.153
M3: Stainless Sheet Steel | N3: 20 | P3: 10 | Q3: 0.127
M4: Carbon Steel Plate | N4: 21 | P4: 12 | Q4: 0.095
M5: Carbon Steel Pipe | N5: 20 | P5: 14 | Q5: 0.067
M6: Carbon Steel Tube | N6: 27 | P6: 16 | Q6: 0.054
M7: Stainless Steel Plate | N7: 17 | P7: 18 | Q7: 0.044
M8: Stainless Steel Pipe | N8: 17 | P8: 11 | Q8: 0.12
M9: Stainless Steel Tube | N9: 17 | P9: 15 | Q9: 0.072
P10: 9 | Q10: 0.148
P11: 13 | Q11: 0.095

Sheet Ryerson Stock Data
A1: Material | B1: Shape | C1: Width | D1: Height | E1: Gauge | F1: Thickness | G1: Chord Width to Thickness | S1: Gauge | T1: Decimal Thickness | U1: Gauge
A2: Carbon Steel Tube | B2: RHS | C2: 1 | D2: 0.5 | E2: 18 | F2: =VLOOKUP(E2,$S$2:$T$10,2,FALSE) -> 0.049 | G2: =F2/C2 -> 0.049 | S2: 11 | T2: 0.12 | U2: 11
A3: Carbon Steel Tube | B3: RHS | C3: 1 | D3: 0.5 | E3: 16 | F3: =VLOOKUP(E3,$S$2:$T$10,2,FALSE) -> 0.065 | G3: =F3/C3 -> 0.065 | S3: 12 | T3: 0.109 | U3: 12
A4: Carbon Steel Tube | B4: RHS | C4: 1 | D4: 0.75 | E4: 16 | F4: =VLOOKUP(E4,$S$2:$T$10,2,FALSE) -> 0.065 | G4: =F4/C4 -> 0.065 | S4: 14 | T4: 0.083 | U4: 14
A5: Carbon Steel Tube | B5: RHS | C5: 1.5 | D5: 0.5 | E5: 16 | F5: =VLOOKUP(E5,$S$2:$T$10,2,FALSE) -> 0.065 | G5: =F5/C5 -> 0.043333333 | S5: 15 | T5: 0.072 | U5: 15
A6: Carbon Steel Tube | B6: RHS | C6: 1.5 | D6: 0.75 | E6: 16 | F6: =VLOOKUP(E6,$S$2:$T$10,2,FALSE) -> 0.065 | G6: =F6/C6 -> 0.043333333 | S6: 16 | T6: 0.065 | U6: 16
A7: Carbon Steel Tube | B7: RHS | C7: 1.5 | D7: 0.75 | E7: 14 | F7: =VLOOKUP(E7,$S$2:$T$10,2,FALSE) -> 0.083 | G7: =F7/C7 -> 0.055333333 | S7: 18 | T7: 0.049 | U7: 18
A8: Carbon Steel Tube | B8: RHS | C8: 1.5 | D8: 0.75 | E8: 11 | F8: =VLOOKUP(E8,$S$2:$T$10,2,FALSE) -> 0.12 | G8: =F8/C8 -> 0.08 | S8: 9 | T8: 0.148 | U8: 9
A9: Carbon Steel Tube | B9: RHS | C9: 1.5 | D9: 1 | E9: 16 | F9: =VLOOKUP(E9,$S$2:$T$10,2,FALSE) -> 0.065 | G9: =F9/C9 -> 0.043333333 | S9: 13 | T9: 0.095 | U9: 13
A10: Carbon Steel Tube | B10: RHS | C10: 1.5 | D10: 1 | E10: 14 | F10: =VLOOKUP(E10,$S$2:$T$10,2,FALSE) -> 0.083 | G10: =F10/C10 -> 0.055333333 | S10: 10 | T10: 0.134 | U10: 10
A11: Carbon Steel Tube | B11: RHS | C11: 1.5 | D11: 1 | E11: 11 | F11: =VLOOKUP(E11,$S$2:$T$10,2,FALSE) -> 0.12 | G11: =F11/C11 -> 0.08
A12: Carbon Steel Tube | B12: RHS | C12: 2 | D12: 0.75 | E12: 16 | F12: =VLOOKUP(E12,$S$2:$T$10,2,FALSE) -> 0.065 | G12: =F12/C12 -> 0.0325
A13: Carbon Steel Tube | B13: RHS | C13: 2 | D13: 1 | E13: 18 | F13: =VLOOKUP(E13,$S$2:$T$10,2,FALSE) -> 0.049 | G13: =F13/C13 -> 0.0245
A14: Carbon Steel Tube | B14: RHS | C14: 2 | D14: 1 | E14: 16 | F14: =VLOOKUP(E14,$S$2:$T$10,2,FALSE) -> 0.065 | G14: =F14/C14 -> 0.0325
A15: Carbon Steel Tube | B15: RHS | C15: 2 | D15: 1 | E15: 15 | F15: =VLOOKUP(E15,$S$2:$T$10,2,FALSE) -> 0.072 | G15: =F15/C15 -> 0.036
A16: Carbon Steel Tube | B16: RHS | C16: 2 | D16: 1 | E16: 14 | F16: =VLOOKUP(E16,$S$2:$T$10,2,FALSE) -> 0.083 | G16: =F16/C16 -> 0.0415
A17: Carbon Steel Tube | B17: RHS | C17: 2 | D17: 1 | E17: 12 | F17: =VLOOKUP(E17,$S$2:$T$10,2,FALSE) -> 0.109 | G17: =F17/C17 -> 0.0545
A18: Carbon Steel Tube | B18: RHS | C18: 2 | D18: 1 | E18: 11 | F18: =VLOOKUP(E18,$S$2:$T$10,2,FALSE) -> 0.12 | G18: =F18/C18 -> 0.06
A19: Carbon Steel Tube | B19: RHS | C19: 2 | D19: 1.25 | E19: 14 | F19: =VLOOKUP(E19,$S$2:$T$10,2,FALSE) -> 0.083 | G19: =F19/C19 -> 0.0415
A20: Carbon Steel Tube | B20: RHS | C20: 2 | D20: 1.5 | E20: 14 | F20: =VLOOKUP(E20,$S$2:$T$10,2,FALSE) -> 0.083 | G20: =F20/C20 -> 0.0415
A21: Carbon Steel Tube | B21: RHS | C21: 2 | D21: 1.5 | E21: 11 | F21: =VLOOKUP(E21,$S$2:$T$10,2,FALSE) -> 0.12 | G21: =F21/C21 -> 0.06
A22: Carbon Steel Tube | B22: RHS | C22: 2.5 | D22: 1 | E22: 14 | F22: =VLOOKUP(E22,$S$2:$T$10,2,FALSE) -> 0.083 | G22: =F22/C22 -> 0.0332
... A25: Carbon Steel Tube | B25: RHS | C25: 2.5 | D25: 1.25 | E25: 11 | F25: =VLOOKUP(E25,$S$2:$T$10,2,FALSE) -> 0.12 | G25: =F25/C25 -> 0.048
A26: Carbon Steel Tube | B26: RHS | C26: 2.5 | D26: 1.25 | F26: 0.125 | G26: =F26/C26 -> 0.05
A27: Carbon Steel Tube | B27: RHS | C27: 2.5 | D27: 1.25 | E27: 9 | F27: =VLOOKUP(E27,$S$2:$T$10,2,FALSE) -> 0.148 | G27: =F27/C27 -> 0.0592
A28: Carbon Steel Tube | B28: RHS | C28: 2.5 | D28: 1.25 | F28: 0.188 | G28: =F28/C28 -> 0.0752
A29: Carbon Steel Tube | B29: RHS | C29: 2.5 | D29: 1.25 | F29: 0.25 | G29: =F29/C29 -> 0.1
A30: Carbon Steel Tube | B30: RHS | C30: 2.5 | D30: 2 | E30: 11 | F30: =VLOOKUP(E30,$S$2:$T$10,2,FALSE) -> 0.12 | G30: =F30/C30 -> 0.048
A31: Carbon Steel Tube | B31: RHS | C31: 3 | D31: 1 | E31: 16 | F31: =VLOOKUP(E31,$S$2:$T$10,2,FALSE) -> 0.065 | G31: =F31/C31 -> 0.021666667
A32: Carbon Steel Tube | B32: RHS | C32: 3 | D32: 1 | E32: 14 | F32: =VLOOKUP(E32,$S$2:$T$10,2,FALSE) -> 0.083 | G32: =F32/C32 -> 0.027666667
A33: Carbon Steel Tube | B33: RHS | C33: 3 | D33: 1 | E33: 11 | F33: =VLOOKUP(E33,$S$2:$T$10,2,FALSE) -> 0.12 | G33: =F33/C33 -> 0.04
A34: Carbon Steel Tube | B34: RHS | C34: 3 | D34: 1.5 | E34: 14 | F34: =VLOOKUP(E34,$S$2:$T$10,2,FALSE) -> 0.083 | G34: =F34/C34 -> 0.027666667
A35: Carbon Steel Tube | B35: RHS | C35: 3 | D35: 1.5 | E35: 13 | F35: =VLOOKUP(E35,$S$2:$T$10,2,FALSE) -> 0.095 | G35: =F35/C35 -> 0.031666667
A36: Carbon Steel Tube | B36: RHS | C36: 3 | D36: 1.5 | E36: 12 | F36: =VLOOKUP(E36,$S$2:$T$10,2,FALSE) -> 0.109 | G36: =F36/C36 -> 0.036333333
A37: Carbon Steel Tube | B37: RHS | C37: 3 | D37: 1.5 | E37: 11 | F37: =VLOOKUP(E37,$S$2:$T$10,2,FALSE) -> 0.12 | G37: =F37/C37 -> 0.04
A38: Carbon Steel Tube | B38: RHS | C38: 3 | D38: 1.5 | F38: 0.125 | G38: =F38/C38 -> 0.041666667
A39: Carbon Steel Tube | B39: RHS | C39: 3 | D39: 1.5 | F39: 0.188 | G39: =F39/C39 -> 0.062666667
A40: Carbon Steel Tube | B40: RHS | C40: 3 | D40: 1.5 | F40: 0.25 | G40: =F40/C40 -> 0.083333333
A41: Carbon Steel Tube | B41: RHS | C41: 3 | D41: 2 | E41: 16 | F41: =VLOOKUP(E41,$S$2:$T$9,2,FALSE) -> 0.065 | G41: =F41/C41 -> 0.021666667
A42: Carbon Steel Tube | B42: RHS | C42: 3 | D42: 2 | E42: 14 | F42: =VLOOKUP(E42,$S$2:$T$9,2,FALSE) -> 0.083 | G42: =F42/C42 -> 0.027666667
...

Sheet Valid Pairs
A1: Branch_W | B1: Branch_H | C1: Branch_t | D1: Branch_Shape | E1: Chord_W | F1: Chord_H | G1: Chord_t | H1: Chord_Shape | I1: Material_out | J1: Width_Ratio | K1: Thickness_Ratio
A2: 1 | B2: 1 | C2: 0.12 | D2: SHS | E2: 1.25 | F2: 1.25 | G2: 0.083 | H2: SHS | I2: Stainless Steel Tube | J2: 0.8 | K2: 1.4457831
A3: 1 | B3: 1 | C3: 0.12 | D3: SHS | E3: 1.5 | F3: 1.5 | G3: 0.065 | H3: SHS | I3: Stainless Steel Tube | J3: 0.66666667 | K3: 1.8461538
A4: 1 | B4: 1 | C4: 0.12 | D4: SHS | E4: 1.5 | F4: 1.5 | G4: 0.083 | H4: SHS | I4: Stainless Steel Tube | J4: 0.66666667 | K4: 1.4457831
A5: 1.25 | B5: 1.25 | C5: 0.083 | D5: SHS | E5: 1.5 | F5: 1.5 | G5: 0.065 | H5: SHS | I5: Stainless Steel Tube | J5: 0.83333333 | K5: 1.2769231
A6: 1.25 | B6: 1.25 | C6: 0.083 | D6: SHS | E6: 2 | F6: 1 | G6: 0.065 | H6: RHS | I6: Stainless Steel Tube | J6: 0.625 | K6: 1.2769231
A7: 1.25 | B7: 1.25 | C7: 0.083 | D7: SHS | E7: 2 | F7: 2 | G7: 0.065 | H7: SHS | I7: Stainless Steel Tube | J7: 0.625 | K7: 1.2769231
A8: 1.25 | B8: 1.25 | C8: 0.12 | D8: SHS | E8: 1.5 | F8: 1.5 | G8: 0.065 | H8: SHS | I8: Stainless Steel Tube | J8: 0.83333333 | K8: 1.8461538
A9: 1.25 | B9: 1.25 | C9: 0.12 | D9: SHS | E9: 1.5 | F9: 1.5 | G9: 0.083 | H9: SHS | I9: Stainless Steel Tube | J9: 0.83333333 | K9: 1.4457831
A10: 1.25 | B10: 1.25 | C10: 0.12 | D10: SHS | E10: 1.75 | F10: 1.75 | G10: 0.083 | H10: SHS | I10: Stainless Steel Tube | J10: 0.71428571 | K10: 1.4457831
A11: 1.25 | B11: 1.25 | C11: 0.12 | D11: SHS | E11: 2 | F11: 1 | G11: 0.065 | H11: RHS | I11: Stainless Steel Tube | J11: 0.625 | K11: 1.8461538
A12: 1.25 | B12: 1.25 | C12: 0.12 | D12: SHS | E12: 2 | F12: 2 | G12: 0.065 | H12: SHS | I12: Stainless Steel Tube | J12: 0.625 | K12: 1.8461538
A13: 1.25 | B13: 1.25 | C13: 0.12 | D13: SHS | E13: 2 | F13: 2 | G13: 0.083 | H13: SHS | I13: Stainless Steel Tube | J13: 0.625 | K13: 1.4457831
... A1306: 8 | B1306: 8 | C1306: 0.375 | D1306: SHS | E1306: 10 | F1306: 8 | G1306: 0.25 | H1306: RHS | I1306: Carbon Steel Tube | J1306: 0.8 | K1306: 1.5

Sheet Linearized Data
A1: Thickness: | B1: ='Valid Pairs'!C2 -> 0.12 | C1: ='Valid Pairs'!G2 -> 0.083 | D1: {=IF(MOD(ROW()-1,2)=0,INDEX(B:B,(ROW()+1)/2),INDEX(C:C,ROW()/2))} -> 0.12 | G1: Width: | H1: ='Valid Pairs'!A2 -> 1 | I1: ='Valid Pairs'!E2 -> 1.25 | J1: {=IF(MOD(ROW()-1,2)=0,INDEX(H:H,(ROW()+1)/2),INDEX(I:I,ROW()/2))} -> 1 | M1: Height: | N1: ='Valid Pairs'!B2 -> 1 | O1: ='Valid Pairs'!F2 -> 1.25 | P1: {=IF(MOD(ROW()-1,2)=0,INDEX(N:N,(ROW()+1)/2),INDEX(O:O,ROW()/2))} -> 1
B2: ='Valid Pairs'!C3 -> 0.12 | C2: ='Valid Pairs'!G3 -> 0.065 | D2: {=IF(MOD(ROW()-1,2)=0,INDEX(B:B,(ROW()+1)/2),INDEX(C:C,ROW()/2))} -> 0.083 | H2: ='Valid Pairs'!A3 -> 1 | I2: ='Valid Pairs'!E3 -> 1.5 | J2: {=IF(MOD(ROW()-1,2)=0,INDEX(H:H,(ROW()+1)/2),INDEX(I:I,ROW()/2))} -> 1.25 | N2: ='Valid Pairs'!B3 -> 1 | O2: ='Valid Pairs'!F3 -> 1.5 | P2: {=IF(MOD(ROW()-1,2)=0,INDEX(N:N,(ROW()+1)/2),INDEX(O:O,ROW()/2))} -> 1.25
B3: ='Valid Pairs'!C4 -> 0.12 | C3: ='Valid Pairs'!G4 -> 0.083 | D3: {=IF(MOD(ROW()-1,2)=0,INDEX(B:B,(ROW()+1)/2),INDEX(C:C,ROW()/2))} -> 0.12 | H3: ='Valid Pairs'!A4 -> 1 | I3: ='Valid Pairs'!E4 -> 1.5 | J3: {=IF(MOD(ROW()-1,2)=0,INDEX(H:H,(ROW()+1)/2),INDEX(I:I,ROW()/2))} -> 1 | N3: ='Valid Pairs'!B4 -> 1 | O3: ='Valid Pairs'!F4 -> 1.5 | P3: {=IF(MOD(ROW()-1,2)=0,INDEX(N:N,(ROW()+1)/2),INDEX(O:O,ROW()/2))} -> 1
B4: ='Valid Pairs'!C5 -> 0.083 | C4: ='Valid Pairs'!G5 -> 0.065 | D4: {=IF(MOD(ROW()-1,2)=0,INDEX(B:B,(ROW()+1)/2),INDEX(C:C,ROW()/2))} -> 0.065 | H4: ='Valid Pairs'!A5 -> 1.25 | I4: ='Valid Pairs'!E5 -> 1.5 | J4: {=IF(MOD(ROW()-1,2)=0,INDEX(H:H,(ROW()+1)/2),INDEX(I:I,ROW()/2))} -> 1.5 | N4: ='Valid Pairs'!B5 -> 1.25 | O4: ='Valid Pairs'!F5 -> 1.5 | P4: {=IF(MOD(ROW()-1,2)=0,INDEX(N:N,(ROW()+1)/2),INDEX(O:O,ROW()/2))} -> 1.5
B5: ='Valid Pairs'!C6 -> 0.083 | C5: ='Valid Pairs'!G6 -> 0.065 | D5: {=IF(MOD(ROW()-1,2)=0,INDEX(B:B,(ROW()+1)/2),INDEX(C:C,ROW()/2))} -> 0.12 | H5: ='Valid Pairs'!A6 -> 1.25 | I5: ='Valid Pairs'!E6 -> 2 | J5: {=IF(MOD(ROW()-1,2)=0,INDEX(H:H,(ROW()+1)/2),INDEX(I:I,ROW()/2))} -> 1 | N5: ='Valid Pairs'!B6 -> 1.25 | O5: ='Valid Pairs'!F6 -> 1 | P5: {=IF(MOD(ROW()-1,2)=0,INDEX(N:N,(ROW()+1)/2),INDEX(O:O,ROW()/2))} -> 1
B6: ='Valid Pairs'!C7 -> 0.083 | C6: ='Valid Pairs'!G7 -> 0.065 | D6: {=IF(MOD(ROW()-1,2)=0,INDEX(B:B,(ROW()+1)/2),INDEX(C:C,ROW()/2))} -> 0.083 | H6: ='Valid Pairs'!A7 -> 1.25 | I6: ='Valid Pairs'!E7 -> 2 | J6: {=IF(MOD(ROW()-1,2)=0,INDEX(H:H,(ROW()+1)/2),INDEX(I:I,ROW()/2))} -> 1.5 | N6: ='Valid Pairs'!B7 -> 1.25 | O6: ='Valid Pairs'!F7 -> 2 | P6: {=IF(MOD(ROW()-1,2)=0,INDEX(N:N,(ROW()+1)/2),INDEX(O:O,ROW()/2))} -> 1.5
B7: ='Valid Pairs'!C8 -> 0.12 | C7: ='Valid Pairs'!G8 -> 0.065 | D7: {=IF(MOD(ROW()-1,2)=0,INDEX(B:B,(ROW()+1)/2),INDEX(C:C,ROW()/2))} -> 0.083 | H7: ='Valid Pairs'!A8 -> 1.25 | I7: ='Valid Pairs'!E8 -> 1.5 | J7: {=IF(MOD(ROW()-1,2)=0,INDEX(H:H,(ROW()+1)/2),INDEX(I:I,ROW()/2))} -> 1.25 | N7: ='Valid Pairs'!B8 -> 1.25 | O7: ='Valid Pairs'!F8 -> 1.5 | P7: {=IF(MOD(ROW()-1,2)=0,INDEX(N:N,(ROW()+1)/2),INDEX(O:O,ROW()/2))} -> 1.25
B8: ='Valid Pairs'!C9 -> 0.12 | C8: ='Valid Pairs'!G9 -> 0.083 | D8: {=IF(MOD(ROW()-1,2)=0,INDEX(B:B,(ROW()+1)/2),INDEX(C:C,ROW()/2))} -> 0.065 | H8: ='Valid Pairs'!A9 -> 1.25 | I8: ='Valid Pairs'!E9 -> 1.5 | J8: {=IF(MOD(ROW()-1,2)=0,INDEX(H:H,(ROW()+1)/2),INDEX(I:I,ROW()/2))} -> 1.5 | N8: ='Valid Pairs'!B9 -> 1.25 | O8: ='Valid Pairs'!F9 -> 1.5 | P8: {=IF(MOD(ROW()-1,2)=0,INDEX(N:N,(ROW()+1)/2),INDEX(O:O,ROW()/2))} -> 1.5
B9: ='Valid Pairs'!C10 -> 0.12 | C9: ='Valid Pairs'!G10 -> 0.083 | D9: {=IF(MOD(ROW()-1,2)=0,INDEX(B:B,(ROW()+1)/2),INDEX(C:C,ROW()/2))} -> 0.083 | H9: ='Valid Pairs'!A10 -> 1.25 | I9: ='Valid Pairs'!E10 -> 1.75 | J9: {=IF(MOD(ROW()-1,2)=0,INDEX(H:H,(ROW()+1)/2),INDEX(I:I,ROW()/2))} -> 1.25 | N9: ='Valid Pairs'!B10 -> 1.25 | O9: ='Valid Pairs'!F10 -> 1.75 | P9: {=IF(MOD(ROW()-1,2)=0,INDEX(N:N,(ROW()+1)/2),INDEX(O:O,ROW()/2))} -> 1.25
B10: ='Valid Pairs'!C11 -> 0.12 | C10: ='Valid Pairs'!G11 -> 0.065 | D10: {=IF(MOD(ROW()-1,2)=0,INDEX(B:B,(ROW()+1)/2),INDEX(C:C,ROW()/2))} -> 0.065 | H10: ='Valid Pairs'!A11 -> 1.25 | I10: ='Valid Pairs'!E11 -> 2 | J10: {=IF(MOD(ROW()-1,2)=0,INDEX(H:H,(ROW()+1)/2),INDEX(I:I,ROW()/2))} -> 2 | N10: ='Valid Pairs'!B11 -> 1.25 | O10: ='Valid Pairs'!F11 -> 1 | P10: {=IF(MOD(ROW()-1,2)=0,INDEX(N:N,(ROW()+1)/2),INDEX(O:O,ROW()/2))} -> 1
B11: ='Valid Pairs'!C12 -> 0.12 | C11: ='Valid Pairs'!G12 -> 0.065 | D11: {=IF(MOD(ROW()-1,2)=0,INDEX(B:B,(ROW()+1)/2),INDEX(C:C,ROW()/2))} -> 0.083 | H11: ='Valid Pairs'!A12 -> 1.25 | I11: ='Valid Pairs'!E12 -> 2 | J11: {=IF(MOD(ROW()-1,2)=0,INDEX(H:H,(ROW()+1)/2),INDEX(I:I,ROW()/2))} -> 1.25 | N11: ='Valid Pairs'!B12 -> 1.25 | O11: ='Valid Pairs'!F12 -> 2 | P11: {=IF(MOD(ROW()-1,2)=0,INDEX(N:N,(ROW()+1)/2),INDEX(O:O,ROW()/2))} -> 1.25
B12: ='Valid Pairs'!C13 -> 0.12 | C12: ='Valid Pairs'!G13 -> 0.083 | D12: {=IF(MOD(ROW()-1,2)=0,INDEX(B:B,(ROW()+1)/2),INDEX(C:C,ROW()/2))} -> 0.065 | H12: ='Valid Pairs'!A13 -> 1.25 | I12: ='Valid Pairs'!E13 -> 2 | J12: {=IF(MOD(ROW()-1,2)=0,INDEX(H:H,(ROW()+1)/2),INDEX(I:I,ROW()/2))} -> 2 | N12: ='Valid Pairs'!B13 -> 1.25 | O12: ='Valid Pairs'!F13 -> 2 | P12: {=IF(MOD(ROW()-1,2)=0,INDEX(N:N,(ROW()+1)/2),INDEX(O:O,ROW()/2))} -> 2
B13: ='Valid Pairs'!C14 -> 0.065 | C13: ='Valid Pairs'!G14 -> 0.049 | D13: {=IF(MOD(ROW()-1,2)=0,INDEX(B:B,(ROW()+1)/2),INDEX(C:C,ROW()/2))} -> 0.12 | H13: ='Valid Pairs'!A14 -> 1.5 | I13: ='Valid Pairs'!E14 -> 2 | J13: {=IF(MOD(ROW()-1,2)=0,INDEX(H:H,(ROW()+1)/2),INDEX(I:I,ROW()/2))} -> 1.25 | N13: ='Valid Pairs'!B14 -> 0.5 | O13: ='Valid Pairs'!F14 -> 1 | P13: {=IF(MOD(ROW()-1,2)=0,INDEX(N:N,(ROW()+1)/2),INDEX(O:O,ROW()/2))} -> 1.25
... B1305: ='Valid Pairs'!C1306 -> 0.375 | C1305: ='Valid Pairs'!G1306 -> 0.25 | D1305: {=IF(MOD(ROW()-1,2)=0,INDEX(B:B,(ROW()+1)/2),INDEX(C:C,ROW()/2))} -> 0.188 | H1305: ='Valid Pairs'!A1306 -> 8 | I1305: ='Valid Pairs'!E1306 -> 10 | J1305: {=IF(MOD(ROW()-1,2)=0,INDEX(H:H,(ROW()+1)/2),INDEX(I:I,ROW()/2))} -> 3 | N1305: ='Valid Pairs'!B1306 -> 8 | O1305: ='Valid Pairs'!F1306 -> 8 | P1305: {=IF(MOD(ROW()-1,2)=0,INDEX(N:N,(ROW()+1)/2),INDEX(O:O,ROW()/2))} -> 2
D1306: {=IF(MOD(ROW()-1,2)=0,INDEX(B:B,(ROW()+1)/2),INDEX(C:C,ROW()/2))} -> 0.12 | J1306: {=IF(MOD(ROW()-1,2)=0,INDEX(H:H,(ROW()+1)/2),INDEX(I:I,ROW()/2))} -> 4 | P1306: {=IF(MOD(ROW()-1,2)=0,INDEX(N:N,(ROW()+1)/2),INDEX(O:O,ROW()/2))} -> 4
D1307: {=IF(MOD(ROW()-1,2)=0,INDEX(B:B,(ROW()+1)/2),INDEX(C:C,ROW()/2))} -> 0.188 | J1307: {=IF(MOD(ROW()-1,2)=0,INDEX(H:H,(ROW()+1)/2),INDEX(I:I,ROW()/2))} -> 3 | P1307: {=IF(MOD(ROW()-1,2)=0,INDEX(N:N,(ROW()+1)/2),INDEX(O:O,ROW()/2))} -> 2
D1308: {=IF(MOD(ROW()-1,2)=0,INDEX(B:B,(ROW()+1)/2),INDEX(C:C,ROW()/2))} -> 0.12 | J1308: {=IF(MOD(ROW()-1,2)=0,INDEX(H:H,(ROW()+1)/2),INDEX(I:I,ROW()/2))} -> 5 | P1308: {=IF(MOD(ROW()-1,2)=0,INDEX(N:N,(ROW()+1)/2),INDEX(O:O,ROW()/2))} -> 2
D1309: {=IF(MOD(ROW()-1,2)=0,INDEX(B:B,(ROW()+1)/2),INDEX(C:C,ROW()/2))} -> 0.188 | J1309: {=IF(MOD(ROW()-1,2)=0,INDEX(H:H,(ROW()+1)/2),INDEX(I:I,ROW()/2))} -> 3 | P1309: {=IF(MOD(ROW()-1,2)=0,INDEX(N:N,(ROW()+1)/2),INDEX(O:O,ROW()/2))} -> 2
D1310: {=IF(MOD(ROW()-1,2)=0,INDEX(B:B,(ROW()+1)/2),INDEX(C:C,ROW()/2))} -> 0.125 | J1310: {=IF(MOD(ROW()-1,2)=0,INDEX(H:H,(ROW()+1)/2),INDEX(I:I,ROW()/2))} -> 5 | P1310: {=IF(MOD(ROW()-1,2)=0,INDEX(N:N,(ROW()+1)/2),INDEX(O:O,ROW()/2))} -> 2
D1311: {=IF(MOD(ROW()-1,2)=0,INDEX(B:B,(ROW()+1)/2),INDEX(C:C,ROW()/2))} -> 0.188 | J1311: {=IF(MOD(ROW()-1,2)=0,INDEX(H:H,(ROW()+1)/2),INDEX(I:I,ROW()/2))} -> 3 | P1311: {=IF(MOD(ROW()-1,2)=0,INDEX(N:N,(ROW()+1)/2),INDEX(O:O,ROW()/2))} -> 2
D1312: {=IF(MOD(ROW()-1,2)=0,INDEX(B:B,(ROW()+1)/2),INDEX(C:C,ROW()/2))} -> 0.134 | J1312: {=IF(MOD(ROW()-1,2)=0,INDEX(H:H,(ROW()+1)/2),INDEX(I:I,ROW()/2))} -> 5 | P1312: {=IF(MOD(ROW()-1,2)=0,INDEX(N:N,(ROW()+1)/2),INDEX(O:O,ROW()/2))} -> 2
D1313: {=IF(MOD(ROW()-1,2)=0,INDEX(B:B,(ROW()+1)/2),INDEX(C:C,ROW()/2))} -> 0.188 | J1313: {=IF(MOD(ROW()-1,2)=0,INDEX(H:H,(ROW()+1)/2),INDEX(I:I,ROW()/2))} -> 3 | P1313: {=IF(MOD(ROW()-1,2)=0,INDEX(N:N,(ROW()+1)/2),INDEX(O:O,ROW()/2))} -> 2
D1314: {=IF(MOD(ROW()-1,2)=0,INDEX(B:B,(ROW()+1)/2),INDEX(C:C,ROW()/2))} -> 0.125 | J1314: {=IF(MOD(ROW()-1,2)=0,INDEX(H:H,(ROW()+1)/2),INDEX(I:I,ROW()/2))} -> 5 | P1314: {=IF(MOD(ROW()-1,2)=0,INDEX(N:N,(ROW()+1)/2),INDEX(O:O,ROW()/2))} -> 2.5
D1315: {=IF(MOD(ROW()-1,2)=0,INDEX(B:B,(ROW()+1)/2),INDEX(C:C,ROW()/2))} -> 0.188 | J1315: {=IF(MOD(ROW()-1,2)=0,INDEX(H:H,(ROW()+1)/2),INDEX(I:I,ROW()/2))} -> 3 | P1315: {=IF(MOD(ROW()-1,2)=0,INDEX(N:N,(ROW()+1)/2),INDEX(O:O,ROW()/2))} -> 2
D1316: {=IF(MOD(ROW()-1,2)=0,INDEX(B:B,(ROW()+1)/2),INDEX(C:C,ROW()/2))} -> 0.12 | J1316: {=IF(MOD(ROW()-1,2)=0,INDEX(H:H,(ROW()+1)/2),INDEX(I:I,ROW()/2))} -> 5 | P1316: {=IF(MOD(ROW()-1,2)=0,INDEX(N:N,(ROW()+1)/2),INDEX(O:O,ROW()/2))} -> 3
D1317: {=IF(MOD(ROW()-1,2)=0,INDEX(B:B,(ROW()+1)/2),INDEX(C:C,ROW()/2))} -> 0.188 | J1317: {=IF(MOD(ROW()-1,2)=0,INDEX(H:H,(ROW()+1)/2),INDEX(I:I,ROW()/2))} -> 3 | P1317: {=IF(MOD(ROW()-1,2)=0,INDEX(N:N,(ROW()+1)/2),INDEX(O:O,ROW()/2))} -> 2
... D2610: {=IF(MOD(ROW()-1,2)=0,INDEX(B:B,(ROW()+1)/2),INDEX(C:C,ROW()/2))} -> 0.25 | J2610: {=IF(MOD(ROW()-1,2)=0,INDEX(H:H,(ROW()+1)/2),INDEX(I:I,ROW()/2))} -> 10 | P2610: {=IF(MOD(ROW()-1,2)=0,INDEX(N:N,(ROW()+1)/2),INDEX(O:O,ROW()/2))} -> 8
